<sdf version='1.7'>
  <model name='cubesat'>
    <link name='frame'>
      <inertial>
        <pose>0 0 0 0 -0 0</pose>
        <mass>0.5</mass>
        <inertia>
          <ixx>0.00333</ixx>
          <ixy>0</ixy>
          <ixz>0</ixz>
          <iyy>0.00333</iyy>
          <iyz>0</iyz>
          <izz>0.00333</izz>
        </inertia>
      </inertial>
      <collision name='frame_collision'>
        <pose>0 0 0 0 -0 0</pose>
        <geometry>
          <box>
            <size>0.1 0.1 0.1</size>
          </box>
        </geometry>
        <surface>
          <contact>
            <ode/>
          </contact>
          <friction>
            <ode/>
          </friction>
        </surface>
      </collision>
      <visual name='frame_visual'>
        <pose>0 0 0 0 -0 0</pose>
        <geometry>
          <box>
            <size>0.1 0.1 0.1</size>
          </box>
        </geometry>
      </visual>
      <gravity>0</gravity>
      <sensor name='imu_sensor' type='imu'>
        <always_on>1</always_on>
        <update_rate>1000</update_rate>
        <visualize>1</visualize>
        <topic>__default_topic__</topic>
        <plugin name='imu_plugin' filename='libgazebo_ros_imu_sensor.so'>
          <topicName>imu</topicName>
          <bodyName>frame</bodyName>
          <updateRateHZ>1000</updateRateHZ>
          <angular_velocity>
            <x>
              <noise type='gaussian'>
                <mean>0.0</mean>
                <stddev>5e-2</stddev>
                <bias_mean>0</bias_mean>
                <bias_stddev>0</bias_stddev>
              </noise>
            </x>
            <y>
              <noise type='gaussian'>
                <mean>0.0</mean>
                <stddev>5e-2</stddev>
                <bias_mean>0</bias_mean>
                <bias_stddev>0</bias_stddev>
              </noise>
            </y>
            <z>
              <noise type='gaussian'>
                <mean>0.0</mean>
                <stddev>5e-2</stddev>
                <bias_mean>0</bias_mean>
                <bias_stddev>0</bias_stddev>
              </noise>
            </z>
          </angular_velocity>
          <orientation>
            <w>
              <noise type='gaussian'>
                <mean>0.0</mean>
                <stddev>5e-2</stddev>
                <bias_mean>0</bias_mean>
                <bias_stddev>0</bias_stddev>
              </noise>
            </w>
            <x>
              <noise type='gaussian'>
                <mean>0.0</mean>
                <stddev>5e-2</stddev>
                <bias_mean>0</bias_mean>
                <bias_stddev>0</bias_stddev>
              </noise>
            </x>
            <y>
              <noise type='gaussian'>
                <mean>0.0</mean>
                <stddev>5e-2</stddev>
                <bias_mean>0</bias_mean>
                <bias_stddev>0</bias_stddev>
              </noise>
            </y>
            <z>
              <noise type='gaussian'>
                <mean>0.0</mean>
                <stddev>5e-2</stddev>
                <bias_mean>0</bias_mean>
                <bias_stddev>0</bias_stddev>
              </noise>
            </z>
          </orientation>
          <xyzOffset>0 0 0</xyzOffset>
          <rpyOffset>0 0 0</rpyOffset>
        </plugin>
        <pose>0 0 0 0 -0 0</pose>
      </sensor>
    </link>
    <joint name='reaction_wheel_x_axis_shaft' type='revolute'>
      <pose relative_to='frame'>0.04 0 0 0 1.57 0</pose>
      <parent>frame</parent>
      <child>reaction_wheel_x_axis</child>
      <axis>
        <xyz>0 0 1</xyz>
        <limit>
          <lower>-1e+16</lower>
          <upper>1e+16</upper>
        </limit>
        <dynamics>
          <spring_reference>0</spring_reference>
          <spring_stiffness>0</spring_stiffness>
        </dynamics>
      </axis>
    </joint>
    <link name='reaction_wheel_x_axis'>
      <pose relative_to='reaction_wheel_x_axis_shaft'>0 0 0 0 -0 0</pose>
      <inertial>
        <pose>0 0 0 0 -0 0</pose>
        <mass>0.5</mass>
        <inertia>
          <ixx>0.0008</ixx>
          <ixy>0</ixy>
          <ixz>0</ixz>
          <iyy>0.000804167</iyy>
          <iyz>0</iyz>
          <izz>0.0016</izz>
        </inertia>
      </inertial>
      <collision name='reaction_wheel_x_axis_collision'>
        <pose>0 0 0 0 -0 0</pose>
        <geometry>
          <cylinder>
            <length>0.005</length>
            <radius>0.035</radius>
          </cylinder>
        </geometry>
        <surface>
          <contact>
            <ode/>
          </contact>
          <friction>
            <ode/>
          </friction>
        </surface>
      </collision>
      <visual name='reaction_wheel_x_axis_visual'>
        <pose>0 0 0 0 -0 0</pose>
        <geometry>
          <cylinder>
            <length>0.005</length>
            <radius>0.035</radius>
          </cylinder>
        </geometry>
        <material>
          <script>
            <name>Gazebo/Red</name>
            <uri>file://media/materials/scripts/gazebo.material</uri>
          </script>
        </material>
      </visual>
      <gravity>0</gravity>
    </link>
    <joint name='reaction_wheel_y_axis_shaft' type='revolute'>
      <pose relative_to='frame'>0 0.04 0 1.57 -0 0</pose>
      <parent>frame</parent>
      <child>reaction_wheel_y_axis</child>
      <axis>
        <xyz>0 0 1</xyz>
        <limit>
          <lower>-1e+16</lower>
          <upper>1e+16</upper>
        </limit>
        <dynamics>
          <spring_reference>0</spring_reference>
          <spring_stiffness>0</spring_stiffness>
        </dynamics>
      </axis>
    </joint>
    <link name='reaction_wheel_y_axis'>
      <pose relative_to='reaction_wheel_y_axis_shaft'>0 0 0 0 -0 0</pose>
      <inertial>
        <pose>0 0 0 0 -0 0</pose>
        <mass>0.5</mass>
        <inertia>
          <ixx>0.000804167</ixx>
          <ixy>0</ixy>
          <ixz>0</ixz>
          <iyy>0.000804167</iyy>
          <iyz>0</iyz>
          <izz>0.0016</izz>
        </inertia>
      </inertial>
      <collision name='reaction_wheel_y_axis_collision'>
        <pose>0 0 0 0 -0 0</pose>
        <geometry>
          <cylinder>
            <length>0.005</length>
            <radius>0.035</radius>
          </cylinder>
        </geometry>
        <surface>
          <contact>
            <ode/>
          </contact>
          <friction>
            <ode/>
          </friction>
        </surface>
      </collision>
      <visual name='reaction_wheel_y_axis_visual'>
        <pose>0 0 0 0 -0 0</pose>
        <geometry>
          <cylinder>
            <length>0.005</length>
            <radius>0.035</radius>
          </cylinder>
        </geometry>
        <material>
          <script>
            <name>Gazebo/Green</name>
            <uri>file://media/materials/scripts/gazebo.material</uri>
          </script>
        </material>
      </visual>
      <gravity>0</gravity>
    </link>
    <joint name='reaction_wheel_z_axis_shaft' type='revolute'>
      <pose relative_to='frame'>0 0 -0.04 0 -0 0</pose>
      <parent>frame</parent>
      <child>reaction_wheel_z_axis</child>
      <axis>
        <xyz>0 0 1</xyz>
        <limit>
          <lower>-1e+16</lower>
          <upper>1e+16</upper>
        </limit>
        <dynamics>
          <spring_reference>0</spring_reference>
          <spring_stiffness>0</spring_stiffness>
        </dynamics>
      </axis>
    </joint>
    <link name='reaction_wheel_z_axis'>
      <pose relative_to='reaction_wheel_z_axis_shaft'>0 0 0 0 -0 0</pose>
      <inertial>
        <pose>0 0 0 0 -0 0</pose>
        <mass>0.5</mass>
        <inertia>
          <ixx>0.000804167</ixx>
          <ixy>0</ixy>
          <ixz>0</ixz>
          <iyy>0.000804167</iyy>
          <iyz>0</iyz>
          <izz>0.0016</izz>
        </inertia>
      </inertial>
      <collision name='reaction_wheel_z_axis_collision'>
        <pose>0 0 0 0 -0 0</pose>
        <geometry>
          <cylinder>
            <length>0.005</length>
            <radius>0.035</radius>
          </cylinder>
        </geometry>
        <surface>
          <contact>
            <ode/>
          </contact>
          <friction>
            <ode/>
          </friction>
        </surface>
      </collision>
      <visual name='reaction_wheel_z_axis_visual'>
        <pose>0 0 0 0 -0 0</pose>
        <geometry>
          <cylinder>
            <length>0.005</length>
            <radius>0.035</radius>
          </cylinder>
        </geometry>
        <material>
          <script>
            <name>Gazebo/Blue</name>
            <uri>file://media/materials/scripts/gazebo.material</uri>
          </script>
        </material>
      </visual>
      <gravity>0</gravity>
    </link>
    <plugin name='dc_motor_reaction_wheel_x' filename='/home/matheuswagner/repos/adaptive-cubesat-adcs/cubesat-simulation/src/cubesat_gazebo/plugins/dc_motor_plugin/build/libdc_motor_plugin.so'>
      <motor_shaft_joint>reaction_wheel_x_axis_shaft</motor_shaft_joint>
    </plugin>
    <plugin name='dc_motor_reaction_wheel_y' filename='/home/matheuswagner/repos/adaptive-cubesat-adcs/cubesat-simulation/src/cubesat_gazebo/plugins/dc_motor_plugin/build/libdc_motor_plugin.so'>
      <motor_shaft_joint>reaction_wheel_y_axis_shaft</motor_shaft_joint>
    </plugin>
    <static>0</static>
    <plugin name='dc_motor_reaction_wheel_z' filename='/home/matheuswagner/repos/adaptive-cubesat-adcs/cubesat-simulation/src/cubesat_gazebo/plugins/dc_motor_plugin/build/libdc_motor_plugin.so'>
      <motor_shaft_joint>reaction_wheel_z_axis_shaft</motor_shaft_joint>
    </plugin>
  </model>
</sdf>
