<?xml version="1.0" ?>
<!-- =================================================================================== -->
<!-- |    This document was autogenerated by xacro from src/cubesat_description/models/cubesat.urdf | -->
<!-- |    EDITING THIS FILE BY HAND IS NOT RECOMMENDED                                 | -->
<!-- =================================================================================== -->
<robot name="cubesat" xmlns:xacro="http://www.ros.org/wiki/xacro">
  <gazebo>
    <plugin name='dc_motor' filename='/home/matheuswagner/repos/adaptive-cubesat-adcs/cubesat-simulation/src/cubesat_gazebo/plugins/dc_motor_plugin/build/libdc_motor_plugin.so'/>
  </gazebo>
  <link name="frame">
    <inertial>
      <origin rpy="0 0 0" xyz="0 0 0"/>
      <mass value="0.5"/>
      <inertia ixx="0.00333" ixy="0.0" ixz="0.0" iyy="0.00333" iyz="0.0" izz="0.00333"/>
    </inertial>
    <collision>
      <origin rpy="0 0 0" xyz="0 0 0"/>
      <geometry>
        <box size="0.1 0.1 0.1"/>
      </geometry>
    </collision>
    <visual>
      <geometry>
        <box size="0.1 0.1 0.1"/>
      </geometry>
    </visual>
  </link>
  <link name="reaction_wheel_x_axis">
    <inertial>
      <origin rpy="0 0 0" xyz="0 0 0"/>
      <mass value="0.5"/>
      <inertia ixx="0.0008" ixy="0.0" ixz="0.0" iyy="0.000804166666667" iyz="0.0" izz="0.0016"/>
    </inertial>
    <collision>
      <origin rpy="0 0 0" xyz="0 0 0"/>
      <geometry>
        <cylinder length="0.005" radius="0.035"/>
      </geometry>
    </collision>
    <visual>
      <geometry>
        <cylinder length="0.005" radius="0.035"/>
      </geometry>
    </visual>
  </link>
  <link name="reaction_wheel_y_axis">
    <inertial>
      <origin rpy="0 0 0" xyz="0 0 0"/>
      <mass value="0.5"/>
      <inertia ixx="0.000804166666667" ixy="0.0" ixz="0.0" iyy="0.000804166666667" iyz="0.0" izz="0.0016"/>
    </inertial>
    <collision>
      <origin rpy="0 0 0" xyz="0 0 0"/>
      <geometry>
        <cylinder length="0.005" radius="0.035"/>
      </geometry>
    </collision>
    <visual>
      <geometry>
        <cylinder length="0.005" radius="0.035"/>
      </geometry>
    </visual>
  </link>
  <link name="reaction_wheel_z_axis">
    <inertial>
      <origin rpy="0 0 0" xyz="0 0 0"/>
      <mass value="0.5"/>
      <inertia ixx="0.000804166666667" ixy="0.0" ixz="0.0" iyy="0.000804166666667" iyz="0.0" izz="0.0016"/>
    </inertial>
    <collision>
      <origin rpy="0 0 0" xyz="0 0 0"/>
      <geometry>
        <cylinder length="0.005" radius="0.035"/>
      </geometry>
    </collision>
    <visual>
      <geometry>
        <cylinder length="0.005" radius="0.035"/>
      </geometry>
    </visual>
  </link>
  <gazebo reference="frame">
    <turnGravityOff>true</turnGravityOff>
  </gazebo>
  <gazebo reference="reaction_wheel_x_axis">
    <turnGravityOff>true</turnGravityOff>
    <material>Gazebo/Red</material>
  </gazebo>
  <gazebo reference="reaction_wheel_y_axis">
    <turnGravityOff>true</turnGravityOff>
    <material>Gazebo/Green</material>
  </gazebo>
  <gazebo reference="reaction_wheel_z_axis">
    <turnGravityOff>true</turnGravityOff>
    <material>Gazebo/Blue</material>
  </gazebo>
  <joint name="reaction_wheel_x_axis_shaft" type="continuous">
    <origin rpy="0 1.57 0" xyz="0.04 0.0 0.0"/>
    <parent link="frame"/>
    <child link="reaction_wheel_x_axis"/>
    <axis xyz="0 0 1"/>
  </joint>
  <joint name="reaction_wheel_y_axis_shaft" type="continuous">
    <origin rpy="1.57 0 0" xyz="0 0.04 0.0"/>
    <parent link="frame"/>
    <child link="reaction_wheel_y_axis"/>
    <axis xyz="0 0 1"/>
  </joint>
  <joint name="reaction_wheel_z_axis_shaft" type="continuous">
    <origin rpy="0 0 0" xyz="0 0 -0.04"/>
    <parent link="frame"/>
    <child link="reaction_wheel_z_axis"/>
    <axis xyz="0 0 1"/>
  </joint>s
  
</robot>