<?xml version="1.0" ?>
<!-- =================================================================================== -->
<!-- |    This document was autogenerated by xacro from src/cubesat_description/models/cubesat.urdf | -->
<!-- |    EDITING THIS FILE BY HAND IS NOT RECOMMENDED                                 | -->
<!-- =================================================================================== -->
<robot name="cubesat" xmlns:xacro="http://www.ros.org/wiki/xacro">
  <link name="frame">
    <inertial>
      <origin rpy="0 0 0" xyz="0 0 0"/>
      <mass value="0.5"/>
      <inertia ixx="0.00222" ixy="0.0" ixz="0.0" iyy="0.00222" iyz="0.0" izz="0.00222"/>
    </inertial>
    <collision>
      <origin rpy="0 0 0" xyz="0 0 0"/>
      <geometry>
        <box size="0.1 0.1 0.1"/>
      </geometry>
    </collision>
    <visual>
      <geometry>
        <box size="0.1 0.1 0.1"/>
      </geometry>
    </visual>
  </link>
  <link name="reaction_wheel_x_axis">
    <inertial>
      <origin rpy="0 0 0" xyz="0 0 0"/>
      <mass value="0.5"/>
      <inertia ixx="0.0000000029" ixy="0.0" ixz="0.0" iyy="0.0000000029" iyz="0.0" izz="0.000000587"/>
    </inertial>
    <collision>
      <origin rpy="0 0 0" xyz="0 0 0"/>
      <geometry>
        <cylinder length="0.005" radius="0.035"/>
      </geometry>
    </collision>
    <visual>
      <geometry>
        <cylinder length="0.005" radius="0.035"/>
      </geometry>
    </visual>
  </link>
  <link name="reaction_wheel_y_axis">
    <inertial>
      <origin rpy="0 0 0" xyz="0 0 0"/>
      <mass value="0.5"/>
      <inertia ixx="0.0000000029" ixy="0.0" ixz="0.0" iyy="0.0000000029" iyz="0.0" izz="0.000000587"/>
    </inertial>
    <collision>
      <origin rpy="0 0 0" xyz="0 0 0"/>
      <geometry>
        <cylinder length="0.005" radius="0.035"/>
      </geometry>
    </collision>
    <visual>
      <geometry>
        <cylinder length="0.005" radius="0.035"/>
      </geometry>
    </visual>
  </link>
  <link name="reaction_wheel_z_axis">
    <inertial>
      <origin rpy="0 0 0" xyz="0 0 0"/>
      <mass value="0.5"/>
      <inertia ixx="0.0000000029" ixy="0.0" ixz="0.0" iyy="0.0000000029" iyz="0.0" izz="0.000000587"/>
    </inertial>
    <collision>
      <origin rpy="0 0 0" xyz="0 0 0"/>
      <geometry>
        <cylinder length="0.005" radius="0.035"/>
      </geometry>
    </collision>
    <visual>
      <geometry>
        <cylinder length="0.005" radius="0.035"/>
      </geometry>
    </visual>
  </link>
  <gazebo reference="frame">
    <turnGravityOff>true</turnGravityOff>
  </gazebo>
  <gazebo reference="reaction_wheel_x_axis">
    <turnGravityOff>true</turnGravityOff>
    <material>Gazebo/Red</material>
  </gazebo>
  <gazebo reference="reaction_wheel_y_axis">
    <turnGravityOff>true</turnGravityOff>
    <material>Gazebo/Green</material>
  </gazebo>
  <gazebo reference="reaction_wheel_z_axis">
    <turnGravityOff>true</turnGravityOff>
    <material>Gazebo/Blue</material>
  </gazebo>
  <joint name="reaction_wheel_x_axis_shaft" type="continuous">
    <origin rpy="0 1.57 0" xyz="0.04 0.0 0.0"/>
    <parent link="frame"/>
    <child link="reaction_wheel_x_axis"/>
    <axis xyz="0 0 1"/>
  </joint>
  <joint name="reaction_wheel_y_axis_shaft" type="continuous">
    <origin rpy="1.57 0 0" xyz="0 0.04 0.0"/>
    <parent link="frame"/>
    <child link="reaction_wheel_y_axis"/>
    <axis xyz="0 0 1"/>
  </joint>
  <joint name="reaction_wheel_z_axis_shaft" type="continuous">
    <origin rpy="0 0 0" xyz="0 0 -0.04"/>
    <parent link="frame"/>
    <child link="reaction_wheel_z_axis"/>
    <axis xyz="0 0 1"/>
  </joint>

    <gazebo>
        <plugin name='dc_motor_reaction_wheel_x'
                filename='/home/matheuswagner/repos/adaptive-cubesat-adcs/cubesat-simulation/src/cubesat_gazebo/plugins/dc_motor_plugin/build/libdc_motor_plugin.so'>
          <motor_shaft_joint>reaction_wheel_x_axis_shaft</motor_shaft_joint>
        </plugin>
    </gazebo>

    <gazebo>
        <plugin name='dc_motor_reaction_wheel_y'
                filename='/home/matheuswagner/repos/adaptive-cubesat-adcs/cubesat-simulation/src/cubesat_gazebo/plugins/dc_motor_plugin/build/libdc_motor_plugin.so'>
          <motor_shaft_joint>reaction_wheel_y_axis_shaft</motor_shaft_joint>
        </plugin>
    </gazebo>

    <gazebo>
        <plugin name='dc_motor_reaction_wheel_z'
                filename='/home/matheuswagner/repos/adaptive-cubesat-adcs/cubesat-simulation/src/cubesat_gazebo/plugins/dc_motor_plugin/build/libdc_motor_plugin.so'>
          <motor_shaft_joint>reaction_wheel_z_axis_shaft</motor_shaft_joint>
        </plugin>
    </gazebo>
    
    <gazebo reference="frame">
      <turnGravityOff>true</turnGravityOff>
      <sensor name="imu_sensor" type="imu">
        <always_on>true</always_on>
        <update_rate>150</update_rate>
        <visualize>1</visualize>
        <topic>__default_topic__</topic>
      <plugin filename="libgazebo_ros_imu_sensor.so" name="imu_plugin">
        <topicName>imu</topicName>
        <bodyName>frame</bodyName>
        <updateRateHZ>200</updateRateHZ>
        <gaussianNoise>0.05</gaussianNoise>
        <xyzOffset>0 0 0</xyzOffset>
        <rpyOffset>0 0 0</rpyOffset>
      </plugin>
      <pose>0 0 0 0 0 0</pose>
    </sensor>
  </gazebo>
  
</robot>